<?xml version="1.0" encoding="utf-8"?>
<robot name="giang">
  <link name="base_link">
    <inertial>
      <origin xyz="0 0 0" rpy="0 0 0" />
      <mass value="4" /> 
      <inertia ixx="0.00190294205026824" ixy="-0.000114075013577605" ixz="-3.93773068625565E-05" iyy="0.00195033809154291" iyz="-0.000339835287344812" izz="0.00302612684815536" />
    </inertial>
    <visual>
      <origin xyz="0 0 0" rpy="0 0 0" />
      <geometry>
        <mesh filename="package://giang/meshes/base_link.STL" />
      </geometry>
      <material name="">
        <color rgba="0.650980392156863 0.619607843137255 0.588235294117647 1" />
      </material>
    </visual>
    <collision>
      <origin xyz="0 0 0" rpy="0 0 0" />
      <geometry>
        <mesh filename="package://giang/meshes/base_link.STL" />
      </geometry>
    </collision>
  </link>
  
  <link name="traicam">
    <inertial>
      <origin xyz="1.11127516957965E-06 0.00454255329124797 0.013285762321554" rpy="0 0 0" />
      <mass value="0.216553757587495" />
      <inertia ixx="4.5330321268905E-05" ixy="2.24020791294186E-09" ixz="1.23633240403192E-09" iyy="4.91826515535104E-05" iyz="1.12578799582933E-05" izz="7.82689182650466E-05" />
    </inertial>
    <visual>
      <origin xyz="0 0 0" rpy="0 0 0" />
      <geometry>
        <mesh filename="package://giang/meshes/traicam.STL" />
      </geometry>
      <material name="">
        <color rgba="0.294117647058824 0.294117647058824 0.294117647058824 1" />
      </material>
    </visual>
    <collision>
      <origin xyz="0 0 0" rpy="0 0 0" />
      <geometry>
        <mesh filename="package://giang/meshes/traicam.STL" />
      </geometry>
    </collision>
  </link>
  
  <joint name="j_traicam" type="continuous">
    <origin xyz="0.07224 -0.12222 -0.061203" rpy="-1.6753 -0.96906 -2.2668" />
    <parent link="base_link" />
    <child link="traicam" />
    <axis xyz="0 0.32332 0.94629" />
  </joint>
  
  <link name="phaicam">
    <inertial>
      <origin xyz="-2.85432592229268E-06 1.19242671126063E-06 -0.0297744682764462" rpy="0 0 0" />
      <mass value="0.2165537429782" />
      <inertia ixx="4.53336998537909E-05" ixy="-2.31768775303798E-09" ixz="-4.78882419731045E-09" iyy="4.53310330222237E-05" iyz="2.76844729913603E-09" izz="8.21171557673177E-05" />
    </inertial>
    <visual>
      <origin xyz="0 0 0" rpy="0 0 0" />
      <geometry>
        <mesh filename="package://giang/meshes/phaicam.STL" />
      </geometry>
      <material name="">
        <color rgba="0.501960784313725 0.501960784313725 0.501960784313725 1" />
      </material>
    </visual>
    <collision>
      <origin xyz="0 0 0" rpy="0 0 0" />
      <geometry>
        <mesh filename="package://giang/meshes/phaicam.STL" />
      </geometry>
    </collision>
  </link>
  
  <joint name="j_phaicam" type="continuous">
    <origin xyz="0.10376 0.1673 0.020053" rpy="-0.79655 -1.2374 -1.324" />
    <parent link="base_link" />
    <child link="phaicam" />
    <axis xyz="0 0 1" />
  </joint>
  
  <link name="saucam">
    <inertial>
      <origin xyz="9.02574320837957E-10 3.2498472427589E-06 0.0768266214061987" rpy="0 0 0" />
      <mass value="0.216553751062434" />
      <inertia ixx="4.53296981278038E-05" ixy="1.37634899950636E-12" ixz="3.56525606834499E-12" iyy="4.53350436706611E-05" iyz="5.53193597537422E-09" izz="8.21171642070257E-05" />
    </inertial>
    <visual>
      <origin xyz="0 0 0" rpy="0 0 0" />
      <geometry>
        <mesh filename="package://giang/meshes/saucam.STL" />
      </geometry>
      <material name="">
        <color rgba="0.752941176470588 0.752941176470588 0.752941176470588 1" />
      </material>
    </visual>
    <collision>
      <origin xyz="0 0 0" rpy="0 0 0" />
      <geometry>
        <mesh filename="package://giang/meshes/saucam.STL" />
      </geometry>
    </collision>
  </link>
  
  <joint name="j_saucam" type="continuous">
    <origin xyz="-0.089592 0.0095916 -0.024209" rpy="-1.5614 -0.55681 1.5374" />
    <parent link="base_link" />
    <child link="saucam" />
    <axis xyz="0 0 1" />
  </joint>
  
  <link name="cam">
    <inertial>
      <origin xyz="-0.00549159067882473 0.000142782093136729 0.00542399688213652" rpy="0 0 0" />
      <mass value="0.00106909376084806" />
      <inertia ixx="1.96245738762131E-08" ixy="-6.82424005356248E-24" ixz="-8.32350491381484E-24" iyy="1.96245738762131E-08" iyz="-3.01920923581855E-23" izz="1.6906568016913E-08" />
    </inertial>
    <visual>
      <origin xyz="0 0 0" rpy="0 0 0" />
      <geometry>
        <mesh filename="package://giang/meshes/cam.STL" />
      </geometry>
      <material name="">
        <color rgba="0.792156862745098 0.819607843137255 0.933333333333333 1" />
      </material>
    </visual>
    <collision>
      <origin xyz="0 0 0" rpy="0 0 0" />
      <geometry>
        <mesh filename="package://giang/meshes/cam.STL" />
      </geometry>
    </collision>
  </link>
  
 <joint name="j_cam" type="fixed">
  <origin xyz="0.05 0 0.01" rpy="0 0.0873 -0.5236" />
  <parent link="base_link" />
  <child link="cam" />
  <axis xyz="0 0 0" />
</joint>
  <link name="lidar">
    <inertial>
      <origin xyz="0 0 0" rpy="0 0 0" /> <!-- Đặt origin về 0 để căn chỉnh -->
      <mass value="0.5" /> <!-- Giữ nguyên như ban đầu -->
      <inertia ixx="0.000449679095584544" ixy="2.81363257557769E-05" ixz="-1.24593204258014E-08" iyy="0.000772785451493485" iyz="8.98983080473076E-08" izz="0.000555359086215568" />
    </inertial>
    <visual>
      <origin xyz="0 0 0" rpy="0 0 0" />
      <geometry>
        <mesh filename="package://giang/meshes/lidar.STL" />
      </geometry>
      <material name="">
        <color rgba="0.792156862745098 0.819607843137255 0.933333333333333 1" />
      </material>
    </visual>
    <collision>
      <origin xyz="0 0 0" rpy="0 0 0" />
      <geometry>
        <mesh filename="package://giang/meshes/lidar.STL" />
      </geometry>
    </collision>
  </link>
  
  <joint name="j_lidar" type="fixed">
    <origin xyz="0 0 0.05" rpy="0 0 0" /> <!-- Đặt ở giữa base_link, nâng lên 0.05m để quét ngang -->
    <parent link="base_link" />
    <child link="lidar" />
    <axis xyz="0 0 0" />
  </joint>
  
  <link name="tt1">
    <inertial>
      <origin xyz="5.55111512312578E-16 -1.41553435639707E-15 0.0817027065570053" rpy="0 0 0" />
      <mass value="0.273318560862312" />
      <inertia ixx="0.0005132055655918" ixy="-2.71050543121376E-20" ixz="-4.36221967835965E-20" iyy="0.000513205565591801" iyz="2.05829006182795E-19" izz="8.96532003518189E-05" />
    </inertial>
    <visual>
      <origin xyz="0 0 0" rpy="0 0 0" />
      <geometry>
        <mesh filename="package://giang/meshes/tt1.STL" />
      </geometry>
      <material name="">
        <color rgba="0.792156862745098 0.819607843137255 0.933333333333333 1" />
      </material>
    </visual>
    <collision>
      <origin xyz="0 0 0" rpy="0 0 0" />
      <geometry>
        <mesh filename="package://giang/meshes/tt1.STL" />
      </geometry>
    </collision>
  </link>
  
  <joint name="j_tt1" type="prismatic">
    <origin xyz="0 6.0234E-05 -0.00021462" rpy="-0.27361 0.0020889 -3.1341" />
    <parent link="base_link" />
    <child link="tt1" />
    <axis xyz="0 0 1" />
    <limit lower="0" upper="0" effort="0" velocity="0" />
  </joint>
  
  <link name="tt2">
    <inertial>
      <origin xyz="5.55111512312578E-17 2.22044604925031E-16 -0.0558509099130727" rpy="0 0 0" />
      <mass value="0.0706858347057703" />
      <inertia ixx="6.28809404570082E-05" ixy="3.17637355220363E-22" ixz="-3.61047793767146E-20" iyy="6.28809404570082E-05" iyz="1.75282880522437E-19" izz="7.95215640439916E-06" />
    </inertial>
    <visual>
      <origin xyz="0 0 0" rpy="0 0 0" />
      <geometry>
        <mesh filename="package://giang/meshes/tt2.STL" />
      </geometry>
      <material name="">
        <color rgba="0.792156862745098 0.819607843137255 0.933333333333333 1" />
      </material>
    </visual>
    <collision>
      <origin xyz="0 0 0" rpy="0 0 0" />
      <geometry>
        <mesh filename="package://giang/meshes/tt2.STL" />
      </geometry>
    </collision>
  </link>
  
  <joint name="j_tt2" type="prismatic">
    <origin xyz="-0.0529676319958768 -0.106682839638125 0.138135732675067" rpy="-1.35924840820937 0.00504628222108553 -0.698372509057435" />
    <parent link="base_link" />
    <child link="tt2" />
    <axis xyz="0 0 1" />
    <limit lower="0" upper="0" effort="0" velocity="0" />
  </joint>

  <!-- Gazebo cho camera -->
  <gazebo reference="cam">
    <sensor type="camera" name="camera1">
      <update_rate>30.0</update_rate>
      <camera name="head">
        <horizontal_fov>1.3962634</horizontal_fov>
        <image>
          <width>800</width>
          <height>800</height>
          <format>R8G8B8</format>
        </image>
        <clip>
          <near>0.02</near>
          <far>300</far>
        </clip>
        <noise>
          <type>gaussian</type>
          <mean>0.0</mean>
          <stddev>0.007</stddev>
        </noise>
      </camera>
      <plugin name="camera_controller" filename="libgazebo_ros_camera.so">
        <alwaysOn>true</alwaysOn>
        <updateRate>30.0</updateRate>
        <cameraName>/giang/camera1</cameraName>
        <imageTopicName>/giang/image_raw</imageTopicName>
        <cameraInfoTopicName>/giang/camera_info</cameraInfoTopicName>
        <frameName>cam</frameName>
      </plugin>
    </sensor>
  </gazebo>

  <!-- Gazebo cho LiDAR (quét 360 độ phương ngang) -->
  <gazebo reference="lidar">
    <sensor type="ray" name="lidar_sensor">
      <pose>0 0 0 0 0 0</pose>
      <visualize>true</visualize>
      <update_rate>30</update_rate>
      <ray>
        <scan>
          <horizontal>
            <samples>720</samples>
            <resolution>1</resolution>
            <min_angle>-3.1416</min_angle>
            <max_angle>3.1416</max_angle>
          </horizontal>
        </scan>
        <range>
          <min>0.1</min>
          <max>30.0</max>
          <resolution>0.01</resolution>
        </range>
        <noise>
          <type>gaussian</type>
          <mean>0.0</mean>
          <stddev>0.01</stddev>
        </noise>
      </ray>
      <plugin name="gazebo_ros_laser" filename="libgazebo_ros_laser.so">
        <topicName>/giang/scan</topicName>
        <frameName>lidar</frameName>
      </plugin>
    </sensor>
  </gazebo>
</robot>